Traceback (most recent call last):
  File "/opt/hostedtoolcache/Python/3.9.21/x64/lib/python3.9/site-packages/jupyter_cache/executors/utils.py", line 58, in single_nb_execution
    executenb(
  File "/opt/hostedtoolcache/Python/3.9.21/x64/lib/python3.9/site-packages/nbclient/client.py", line 1319, in execute
    return NotebookClient(nb=nb, resources=resources, km=km, **kwargs).execute()
  File "/opt/hostedtoolcache/Python/3.9.21/x64/lib/python3.9/site-packages/jupyter_core/utils/__init__.py", line 165, in wrapped
    return loop.run_until_complete(inner)
  File "/opt/hostedtoolcache/Python/3.9.21/x64/lib/python3.9/asyncio/base_events.py", line 647, in run_until_complete
    return future.result()
  File "/opt/hostedtoolcache/Python/3.9.21/x64/lib/python3.9/site-packages/nbclient/client.py", line 709, in async_execute
    await self.async_execute_cell(
  File "/opt/hostedtoolcache/Python/3.9.21/x64/lib/python3.9/site-packages/nbclient/client.py", line 1062, in async_execute_cell
    await self._check_raise_for_error(cell, cell_index, exec_reply)
  File "/opt/hostedtoolcache/Python/3.9.21/x64/lib/python3.9/site-packages/nbclient/client.py", line 918, in _check_raise_for_error
    raise CellExecutionError.from_cell_and_msg(cell, exec_reply_content)
nbclient.exceptions.CellExecutionError: An error occurred while executing the following cell:
------------------
%reload_ext autoreload
%autoreload 2
%matplotlib inline

import pymarc
from pymarcspec import MarcSearchParser
import spacy

marc_parser = MarcSearchParser()
with open("data/yale-dvd-records.mrc", "rb") as fo:
    marc_reader = pymarc.MARCReader(fo.read())
marc_records = [r for r in marc_reader]
------------------


[0;31m---------------------------------------------------------------------------[0m
[0;31mFileNotFoundError[0m                         Traceback (most recent call last)
Cell [0;32mIn[1], line 10[0m
[1;32m      7[0m [38;5;28;01mimport[39;00m[38;5;250m [39m[38;5;21;01mspacy[39;00m
[1;32m      9[0m marc_parser [38;5;241m=[39m MarcSearchParser()
[0;32m---> 10[0m [38;5;28;01mwith[39;00m [38;5;28;43mopen[39;49m[43m([49m[38;5;124;43m"[39;49m[38;5;124;43mdata/yale-dvd-records.mrc[39;49m[38;5;124;43m"[39;49m[43m,[49m[43m [49m[38;5;124;43m"[39;49m[38;5;124;43mrb[39;49m[38;5;124;43m"[39;49m[43m)[49m [38;5;28;01mas[39;00m fo:
[1;32m     11[0m     marc_reader [38;5;241m=[39m pymarc[38;5;241m.[39mMARCReader(fo[38;5;241m.[39mread())
[1;32m     12[0m marc_records [38;5;241m=[39m [r [38;5;28;01mfor[39;00m r [38;5;129;01min[39;00m marc_reader]

File [0;32m/opt/hostedtoolcache/Python/3.9.21/x64/lib/python3.9/site-packages/IPython/core/interactiveshell.py:310[0m, in [0;36m_modified_open[0;34m(file, *args, **kwargs)[0m
[1;32m    303[0m [38;5;28;01mif[39;00m file [38;5;129;01min[39;00m {[38;5;241m0[39m, [38;5;241m1[39m, [38;5;241m2[39m}:
[1;32m    304[0m     [38;5;28;01mraise[39;00m [38;5;167;01mValueError[39;00m(
[1;32m    305[0m         [38;5;124mf[39m[38;5;124m"[39m[38;5;124mIPython won[39m[38;5;124m'[39m[38;5;124mt let you open fd=[39m[38;5;132;01m{[39;00mfile[38;5;132;01m}[39;00m[38;5;124m by default [39m[38;5;124m"[39m
[1;32m    306[0m         [38;5;124m"[39m[38;5;124mas it is likely to crash IPython. If you know what you are doing, [39m[38;5;124m"[39m
[1;32m    307[0m         [38;5;124m"[39m[38;5;124myou can use builtins[39m[38;5;124m'[39m[38;5;124m open.[39m[38;5;124m"[39m
[1;32m    308[0m     )
[0;32m--> 310[0m [38;5;28;01mreturn[39;00m [43mio_open[49m[43m([49m[43mfile[49m[43m,[49m[43m [49m[38;5;241;43m*[39;49m[43margs[49m[43m,[49m[43m [49m[38;5;241;43m*[39;49m[38;5;241;43m*[39;49m[43mkwargs[49m[43m)[49m

[0;31mFileNotFoundError[0m: [Errno 2] No such file or directory: 'data/yale-dvd-records.mrc'

